<?xml version="1.0" encoding="utf-8"?>
<!-- This URDF was automatically created by SolidWorks to URDF Exporter! Originally created by Stephen Brawner (brawner@gmail.com) 
     Commit Version: 1.6.0-1-g15f4949  Build Version: 1.6.7594.29634
     For more information, please see http://wiki.ros.org/sw_urdf_exporter -4.00707325784361E-05 0.000956208219399799 0.0208751569691421 -->
<robot
  name="omni_robot">
  <link
    name="base_link">
    <inertial>
      <origin
        xyz="0 0 0"
        rpy="0 0 0" />
      <mass
        value="100" />
      <inertia
        ixx="1"
        ixy="1"
        ixz="1"
        iyy="1"
        iyz="1"
        izz="1" />
    </inertial>
    <visual>
      <origin
        xyz="0 0 0"
        rpy="0 0 0" />
      <geometry>
        <mesh
          filename="package://omni_robot/meshes/base_link.STL" />
      </geometry>
      <material
        name="">
        <color
          rgba="0.698039215686274 0.698039215686274 0.698039215686274 1" />
      </material>
    </visual>
    <collision>
      <origin
        xyz="0 0 0"
        rpy="0 0 0" />
      <geometry>
        <mesh
          filename="package://omni_robot/meshes/base_link.STL" />
      </geometry>
    </collision>
  </link>
  <link
    name="Wheel_Front_Left">
    <inertial>
      <origin
        xyz="7.1109E-06 7.3026E-07 0.037241"
        rpy="0 0 0" />
      <mass
        value="1" />
      <inertia
        ixx="1"
        ixy="1"
        ixz="1"
        iyy="1"
        iyz="1"
        izz="1" />
    </inertial>
    <visual>
      <origin
        xyz="0 0 0"
        rpy="0 0 0" />
      <geometry>
        <mesh
          filename="package://omni_robot/meshes/Wheel_Front_Left.STL" />
      </geometry>
      <material
        name="">
        <color
          rgba="0.69804 0.69804 0.69804 1" />
      </material>
    </visual>
    <collision>
      <origin
        xyz="0 0 0"
        rpy="0 0 0" />
      <geometry>
        <mesh
          filename="package://omni_robot/meshes/Wheel_Front_Left.STL" />
      </geometry>
    </collision>
  </link>
  <joint
    name="joint_wfl"
    type="continuous">
    <origin
      xyz="0.0416098206774492 -0.0150000000000001 0.0416083105634271"
      rpy="-0.602251260331519 -0.539288345735426 -2.21237715789433" />
    <parent
      link="base_link" />
    <child
      link="Wheel_Front_Left" />
    <axis
      xyz="0 0 1" />
  </joint>
  <link
    name="Wheel_secondary_fl1">
    <inertial>
      <origin
        xyz="2.7756E-17 0 0"
        rpy="0 0 0" />
      <mass
        value="0.0012665" />
      <inertia
        ixx="0"
        ixy="0"
        ixz="0"
        iyy="0"
        iyz="0"
        izz="0" />
    </inertial>
    <visual>
      <origin
        xyz="0 0 0"
        rpy="0 0 0" />
      <geometry>
        <mesh
          filename="package://omni_robot/meshes/Wheel_secondary_fl1.STL" />
      </geometry>
      <material
        name="">
        <color
          rgba="0.69804 0.69804 0.69804 1" />
      </material>
    </visual>
    <collision>
      <origin
        xyz="0 0 0"
        rpy="0 0 0" />
      <geometry>
        <mesh
          filename="package://omni_robot/meshes/Wheel_secondary_fl1.STL" />
      </geometry>
    </collision>
  </link>
  <joint
    name="joint_wsfl1"
    type="continuous">
    <origin
      xyz="0.0094129 0.009475 0.043736"
      rpy="-1.5967 0 -0.78387" />
    <parent
      link="Wheel_Front_Left" />
    <child
      link="Wheel_secondary_fl1" />
    <axis
      xyz="1 0 0" />
  </joint>
  <link
    name="Wheel_secondary_fl2">
    <inertial>
      <origin
        xyz="-6.9389E-18 0 0"
        rpy="0 0 0" />
      <mass
        value="0.0012665" />
      <inertia
        ixx="0"
        ixy="0"
        ixz="0"
        iyy="0"
        iyz="0"
        izz="0" />
    </inertial>
    <visual>
      <origin
        xyz="0 0 0"
        rpy="0 0 0" />
      <geometry>
        <mesh
          filename="package://omni_robot/meshes/Wheel_secondary_fl2.STL" />
      </geometry>
      <material
        name="">
        <color
          rgba="0.69804 0.69804 0.69804 1" />
      </material>
    </visual>
    <collision>
      <origin
        xyz="0 0 0"
        rpy="0 0 0" />
      <geometry>
        <mesh
          filename="package://omni_robot/meshes/Wheel_secondary_fl2.STL" />
      </geometry>
    </collision>
  </link>
  <joint
    name="joint_wsfl2"
    type="continuous">
    <origin
      xyz="0.009453 -0.009453 0.043736"
      rpy="-2.356 0 -2.3562" />
    <parent
      link="Wheel_Front_Left" />
    <child
      link="Wheel_secondary_fl2" />
    <axis
      xyz="-1 0 0" />
  </joint>
  <link
    name="Wheel_secondary_fl3">
    <inertial>
      <origin
        xyz="0 0 -6.5052E-19"
        rpy="0 0 0" />
      <mass
        value="0.0012665" />
      <inertia
        ixx="0"
        ixy="0"
        ixz="0"
        iyy="0"
        iyz="0"
        izz="0" />
    </inertial>
    <visual>
      <origin
        xyz="0 0 0"
        rpy="0 0 0" />
      <geometry>
        <mesh
          filename="package://omni_robot/meshes/Wheel_secondary_fl3.STL" />
      </geometry>
      <material
        name="">
        <color
          rgba="0.69804 0.69804 0.69804 1" />
      </material>
    </visual>
    <collision>
      <origin
        xyz="0 0 0"
        rpy="0 0 0" />
      <geometry>
        <mesh
          filename="package://omni_robot/meshes/Wheel_secondary_fl3.STL" />
      </geometry>
    </collision>
  </link>
  <joint
    name="joint_wsfl3"
    type="continuous">
    <origin
      xyz="-0.0094642 -0.0094599 0.043736"
      rpy="1.5967 0 2.3577" />
    <parent
      link="Wheel_Front_Left" />
    <child
      link="Wheel_secondary_fl3" />
    <axis
      xyz="-1 0 0" />
  </joint>
  <link
    name="Wheel_secondary_fl4">
    <inertial>
      <origin
        xyz="6.9389E-18 0 0"
        rpy="0 0 0" />
      <mass
        value="0.0012665" />
      <inertia
        ixx="0"
        ixy="0"
        ixz="0"
        iyy="0"
        iyz="0"
        izz="0" />
    </inertial>
    <visual>
      <origin
        xyz="0 0 0"
        rpy="0 0 0" />
      <geometry>
        <mesh
          filename="package://omni_robot/meshes/Wheel_secondary_fl4.STL" />
      </geometry>
      <material
        name="">
        <color
          rgba="0.69804 0.69804 0.69804 1" />
      </material>
    </visual>
    <collision>
      <origin
        xyz="0 0 0"
        rpy="0 0 0" />
      <geometry>
        <mesh
          filename="package://omni_robot/meshes/Wheel_secondary_fl4.STL" />
      </geometry>
    </collision>
  </link>
  <joint
    name="joint_wsfl4"
    type="continuous">
    <origin
      xyz="-0.009453 0.009453 0.043736"
      rpy="2.356 0 0.7854" />
    <parent
      link="Wheel_Front_Left" />
    <child
      link="Wheel_secondary_fl4" />
    <axis
      xyz="1 0 0" />
  </joint>
  <link
    name="Wheel_secondary_fl5">
    <inertial>
      <origin
        xyz="1.7347E-17 0 -6.9389E-18"
        rpy="0 0 0" />
      <mass
        value="0.0012665" />
      <inertia
        ixx="0"
        ixy="0"
        ixz="0"
        iyy="0"
        iyz="0"
        izz="0" />
    </inertial>
    <visual>
      <origin
        xyz="0 0 0"
        rpy="0 0 0" />
      <geometry>
        <mesh
          filename="package://omni_robot/meshes/Wheel_secondary_fl5.STL" />
      </geometry>
      <material
        name="">
        <color
          rgba="0.69804 0.69804 0.69804 1" />
      </material>
    </visual>
    <collision>
      <origin
        xyz="0 0 0"
        rpy="0 0 0" />
      <geometry>
        <mesh
          filename="package://omni_robot/meshes/Wheel_secondary_fl5.STL" />
      </geometry>
    </collision>
  </link>
  <joint
    name="joint_wsfl5"
    type="continuous">
    <origin
      xyz="0.013369 0 0.030736"
      rpy="0.94268 0 -1.5708" />
    <parent
      link="Wheel_Front_Left" />
    <child
      link="Wheel_secondary_fl5" />
    <axis
      xyz="1 0 0" />
  </joint>
  <link
    name="Wheel_secondary_fl6">
    <inertial>
      <origin
        xyz="-1.0408E-17 0 -1.3878E-17"
        rpy="0 0 0" />
      <mass
        value="0.0012665" />
      <inertia
        ixx="0"
        ixy="0"
        ixz="0"
        iyy="0"
        iyz="0"
        izz="0" />
    </inertial>
    <visual>
      <origin
        xyz="0 0 0"
        rpy="0 0 0" />
      <geometry>
        <mesh
          filename="package://omni_robot/meshes/Wheel_secondary_fl6.STL" />
      </geometry>
      <material
        name="">
        <color
          rgba="0.69804 0.69804 0.69804 1" />
      </material>
    </visual>
    <collision>
      <origin
        xyz="0 0 0"
        rpy="0 0 0" />
      <geometry>
        <mesh
          filename="package://omni_robot/meshes/Wheel_secondary_fl6.STL" />
      </geometry>
    </collision>
  </link>
  <joint
    name="joint_wsfl6"
    type="continuous">
    <origin
      xyz="0 -0.013369 0.030736"
      rpy="0.96855 0 3.1416" />
    <parent
      link="Wheel_Front_Left" />
    <child
      link="Wheel_secondary_fl6" />
    <axis
      xyz="-1 0 0" />
  </joint>
  <link
    name="Wheel_secondary_fl7">
    <inertial>
      <origin
        xyz="2.6021E-18 0 0"
        rpy="0 0 0" />
      <mass
        value="0.0012665" />
      <inertia
        ixx="0"
        ixy="0"
        ixz="0"
        iyy="0"
        iyz="0"
        izz="0" />
    </inertial>
    <visual>
      <origin
        xyz="0 0 0"
        rpy="0 0 0" />
      <geometry>
        <mesh
          filename="package://omni_robot/meshes/Wheel_secondary_fl7.STL" />
      </geometry>
      <material
        name="">
        <color
          rgba="0.69804 0.69804 0.69804 1" />
      </material>
    </visual>
    <collision>
      <origin
        xyz="0 0 0"
        rpy="0 0 0" />
      <geometry>
        <mesh
          filename="package://omni_robot/meshes/Wheel_secondary_fl7.STL" />
      </geometry>
    </collision>
  </link>
  <joint
    name="joint_wsfl7"
    type="continuous">
    <origin
      xyz="-0.013369 0 0.030736"
      rpy="2.173 0 0" />
    <parent
      link="Wheel_Front_Left" />
    <child
      link="Wheel_secondary_fl7" />
    <axis
      xyz="0 0.5665 0.82406" />
  </joint>
  <link
    name="Wheel_secondary_fl8">
    <inertial>
      <origin
        xyz="1.0408E-17 0 1.3878E-17"
        rpy="0 0 0" />
      <mass
        value="0.0012665" />
      <inertia
        ixx="0"
        ixy="0"
        ixz="0"
        iyy="0"
        iyz="0"
        izz="0" />
    </inertial>
    <visual>
      <origin
        xyz="0 0 0"
        rpy="0 0 0" />
      <geometry>
        <mesh
          filename="package://omni_robot/meshes/Wheel_secondary_fl8.STL" />
      </geometry>
      <material
        name="">
        <color
          rgba="0.69804 0.69804 0.69804 1" />
      </material>
    </visual>
    <collision>
      <origin
        xyz="0 0 0"
        rpy="0 0 0" />
      <geometry>
        <mesh
          filename="package://omni_robot/meshes/Wheel_secondary_fl8.STL" />
      </geometry>
    </collision>
  </link>
  <joint
    name="joint_wsfl8"
    type="continuous">
    <origin
      xyz="0 0.013369 0.030736"
      rpy="2.173 0 0" />
    <parent
      link="Wheel_Front_Left" />
    <child
      link="Wheel_secondary_fl8" />
    <axis
      xyz="1 0 0" />
  </joint>
  <link
    name="Wheel_Front_Right">
    <inertial>
      <origin
        xyz="7.111E-06 7.3042E-07 4.8012E-06"
        rpy="0 0 0" />
      <mass
        value="1" />
      <inertia
        ixx="1"
        ixy="1"
        ixz="1"
        iyy="1"
        iyz="1"
        izz="1" />
    </inertial>
    <visual>
      <origin
        xyz="0 0 0"
        rpy="0 0 0" />
      <geometry>
        <mesh
          filename="package://omni_robot/meshes/Wheel_Front_Right.STL" />
      </geometry>
      <material
        name="">
        <color
          rgba="0.69804 0.69804 0.69804 1" />
      </material>
    </visual>
    <collision>
      <origin
        xyz="0 0 0"
        rpy="0 0 0" />
      <geometry>
        <mesh
          filename="package://omni_robot/meshes/Wheel_Front_Right.STL" />
      </geometry>
    </collision>
  </link>
  <joint
    name="joint_wfr"
    type="continuous">
    <origin
      xyz="-0.0680462979171706 -0.015 0.0679398825356011"
      rpy="0.608543943241512 -0.531950234276149 -0.941544856782788" />
    <parent
      link="base_link" />
    <child
      link="Wheel_Front_Right" />
    <axis
      xyz="0 0 1" />
  </joint>
  <link
    name="Wheel_secondary_fr1">
    <inertial>
      <origin
        xyz="5.2042E-18 1.3878E-17 0"
        rpy="0 0 0" />
      <mass
        value="0.0012665" />
      <inertia
        ixx="0"
        ixy="0"
        ixz="0"
        iyy="0"
        iyz="0"
        izz="0" />
    </inertial>
    <visual>
      <origin
        xyz="0 0 0"
        rpy="0 0 0" />
      <geometry>
        <mesh
          filename="package://omni_robot/meshes/Wheel_secondary_fr1.STL" />
      </geometry>
      <material
        name="">
        <color
          rgba="0.69804 0.69804 0.69804 1" />
      </material>
    </visual>
    <collision>
      <origin
        xyz="0 0 0"
        rpy="0 0 0" />
      <geometry>
        <mesh
          filename="package://omni_robot/meshes/Wheel_secondary_fr1.STL" />
      </geometry>
    </collision>
  </link>
  <joint
    name="joint_wsfr1"
    type="continuous">
    <origin
      xyz="0.0094129 0.009475 0.0065"
      rpy="0.78546 0 -0.78387" />
    <parent
      link="Wheel_Front_Right" />
    <child
      link="Wheel_secondary_fr1" />
    <axis
      xyz="1 0 0" />
  </joint>
  <link
    name="Wheel_secondary_fr2">
    <inertial>
      <origin
        xyz="-2.0817E-17 0 0"
        rpy="0 0 0" />
      <mass
        value="0.0012665" />
      <inertia
        ixx="0"
        ixy="0"
        ixz="0"
        iyy="0"
        iyz="0"
        izz="0" />
    </inertial>
    <visual>
      <origin
        xyz="0 0 0"
        rpy="0 0 0" />
      <geometry>
        <mesh
          filename="package://omni_robot/meshes/Wheel_secondary_fr2.STL" />
      </geometry>
      <material
        name="">
        <color
          rgba="0.69804 0.69804 0.69804 1" />
      </material>
    </visual>
    <collision>
      <origin
        xyz="0 0 0"
        rpy="0 0 0" />
      <geometry>
        <mesh
          filename="package://omni_robot/meshes/Wheel_secondary_fr2.STL" />
      </geometry>
    </collision>
  </link>
  <joint
    name="joint_wsfr2"
    type="continuous">
    <origin
      xyz="0.009453 -0.009453 0.0065"
      rpy="1.5563 0 -2.3562" />
    <parent
      link="Wheel_Front_Right" />
    <child
      link="Wheel_secondary_fr2" />
    <axis
      xyz="-1 0 0" />
  </joint>
  <link
    name="Wheel_secondary_fr3">
    <inertial>
      <origin
        xyz="-1.0408E-17 0 0"
        rpy="0 0 0" />
      <mass
        value="0.0012665" />
      <inertia
        ixx="0"
        ixy="0"
        ixz="0"
        iyy="0"
        iyz="0"
        izz="0" />
    </inertial>
    <visual>
      <origin
        xyz="0 0 0"
        rpy="0 0 0" />
      <geometry>
        <mesh
          filename="package://omni_robot/meshes/Wheel_secondary_fr3.STL" />
      </geometry>
      <material
        name="">
        <color
          rgba="0.69804 0.69804 0.69804 1" />
      </material>
    </visual>
    <collision>
      <origin
        xyz="0 0 0"
        rpy="0 0 0" />
      <geometry>
        <mesh
          filename="package://omni_robot/meshes/Wheel_secondary_fr3.STL" />
      </geometry>
    </collision>
  </link>
  <joint
    name="joint_wsfr3"
    type="continuous">
    <origin
      xyz="-0.0094642 -0.0094599 0.0065"
      rpy="2.3561 0 2.3577" />
    <parent
      link="Wheel_Front_Right" />
    <child
      link="Wheel_secondary_fr3" />
    <axis
      xyz="-1 0 0" />
  </joint>
  <link
    name="Wheel_secondary_fr4">
    <inertial>
      <origin
        xyz="1.3878E-17 1.3878E-17 2.1684E-19"
        rpy="0 0 0" />
      <mass
        value="0.0012665" />
      <inertia
        ixx="0"
        ixy="0"
        ixz="0"
        iyy="0"
        iyz="0"
        izz="0" />
    </inertial>
    <visual>
      <origin
        xyz="0 0 0"
        rpy="0 0 0" />
      <geometry>
        <mesh
          filename="package://omni_robot/meshes/Wheel_secondary_fr4.STL" />
      </geometry>
      <material
        name="">
        <color
          rgba="0.69804 0.69804 0.69804 1" />
      </material>
    </visual>
    <collision>
      <origin
        xyz="0 0 0"
        rpy="0 0 0" />
      <geometry>
        <mesh
          filename="package://omni_robot/meshes/Wheel_secondary_fr4.STL" />
      </geometry>
    </collision>
  </link>
  <joint
    name="joint_wsfr4"
    type="continuous">
    <origin
      xyz="-0.009453 0.009453 0.0065"
      rpy="1.5853 0 0.7854" />
    <parent
      link="Wheel_Front_Right" />
    <child
      link="Wheel_secondary_fr4" />
    <axis
      xyz="1 0 0" />
  </joint>
  <link
    name="Wheel_secondary_fr5">
    <inertial>
      <origin
        xyz="-1.0408E-17 -1.3878E-17 -2.7756E-17"
        rpy="0 0 0" />
      <mass
        value="0.0012665" />
      <inertia
        ixx="0"
        ixy="0"
        ixz="0"
        iyy="0"
        iyz="0"
        izz="0" />
    </inertial>
    <visual>
      <origin
        xyz="0 0 0"
        rpy="0 0 0" />
      <geometry>
        <mesh
          filename="package://omni_robot/meshes/Wheel_secondary_fr5.STL" />
      </geometry>
      <material
        name="">
        <color
          rgba="0.69804 0.69804 0.69804 1" />
      </material>
    </visual>
    <collision>
      <origin
        xyz="0 0 0"
        rpy="0 0 0" />
      <geometry>
        <mesh
          filename="package://omni_robot/meshes/Wheel_secondary_fr5.STL" />
      </geometry>
    </collision>
  </link>
  <joint
    name="joint_wsfr5"
    type="continuous">
    <origin
      xyz="0.013369 0 -0.0065"
      rpy="0.94855 0 -1.5708" />
    <parent
      link="Wheel_Front_Right" />
    <child
      link="Wheel_secondary_fr5" />
    <axis
      xyz="1 0 0" />
  </joint>
  <link
    name="Wheel_secondary_fr6">
    <inertial>
      <origin
        xyz="-3.8164E-17 -1.3878E-17 4.1633E-17"
        rpy="0 0 0" />
      <mass
        value="0.0012665" />
      <inertia
        ixx="0"
        ixy="0"
        ixz="0"
        iyy="0"
        iyz="0"
        izz="0" />
    </inertial>
    <visual>
      <origin
        xyz="0 0 0"
        rpy="0 0 0" />
      <geometry>
        <mesh
          filename="package://omni_robot/meshes/Wheel_secondary_fr6.STL" />
      </geometry>
      <material
        name="">
        <color
          rgba="0.69804 0.69804 0.69804 1" />
      </material>
    </visual>
    <collision>
      <origin
        xyz="0 0 0"
        rpy="0 0 0" />
      <geometry>
        <mesh
          filename="package://omni_robot/meshes/Wheel_secondary_fr6.STL" />
      </geometry>
    </collision>
  </link>
  <joint
    name="joint_wsfr6"
    type="continuous">
    <origin
      xyz="0 -0.013369 -0.0065"
      rpy="2.1793 0 -3.1416" />
    <parent
      link="Wheel_Front_Right" />
    <child
      link="Wheel_secondary_fr6" />
    <axis
      xyz="-1 0 0" />
  </joint>
  <link
    name="Wheel_secondary_fr7">
    <inertial>
      <origin
        xyz="2.949E-17 0 4.1633E-17"
        rpy="0 0 0" />
      <mass
        value="0.0012665" />
      <inertia
        ixx="0"
        ixy="0"
        ixz="0"
        iyy="0"
        iyz="0"
        izz="0" />
    </inertial>
    <visual>
      <origin
        xyz="0 0 0"
        rpy="0 0 0" />
      <geometry>
        <mesh
          filename="package://omni_robot/meshes/Wheel_secondary_fr7.STL" />
      </geometry>
      <material
        name="">
        <color
          rgba="0.69804 0.69804 0.69804 1" />
      </material>
    </visual>
    <collision>
      <origin
        xyz="0 0 0"
        rpy="0 0 0" />
      <geometry>
        <mesh
          filename="package://omni_robot/meshes/Wheel_secondary_fr7.STL" />
      </geometry>
    </collision>
  </link>
  <joint
    name="joint_wsfr7"
    type="continuous">
    <origin
      xyz="-0.013369 0 -0.0065"
      rpy="2.193 0 1.5708" />
    <parent
      link="Wheel_Front_Right" />
    <child
      link="Wheel_secondary_fr7" />
    <axis
      xyz="-1 0 0" />
  </joint>
  <link
    name="Wheel_secondary_fr8">
    <inertial>
      <origin
        xyz="2.7756E-17 -2.7756E-17 -2.0817E-17"
        rpy="0 0 0" />
      <mass
        value="0.0012665" />
      <inertia
        ixx="0"
        ixy="0"
        ixz="0"
        iyy="0"
        iyz="0"
        izz="0" />
    </inertial>
    <visual>
      <origin
        xyz="0 0 0"
        rpy="0 0 0" />
      <geometry>
        <mesh
          filename="package://omni_robot/meshes/Wheel_secondary_fr8.STL" />
      </geometry>
      <material
        name="">
        <color
          rgba="0.69804 0.69804 0.69804 1" />
      </material>
    </visual>
    <collision>
      <origin
        xyz="0 0 0"
        rpy="0 0 0" />
      <geometry>
        <mesh
          filename="package://omni_robot/meshes/Wheel_secondary_fr8.STL" />
      </geometry>
    </collision>
  </link>
  <joint
    name="joint_wsfr8"
    type="continuous">
    <origin
      xyz="0 0.013369 -0.0065"
      rpy="0.96225 0 0" />
    <parent
      link="Wheel_Front_Right" />
    <child
      link="Wheel_secondary_fr8" />
    <axis
      xyz="1 0 0" />
  </joint>
  <link
    name="Wheel_Back_Right">
    <inertial>
      <origin
        xyz="7.1109E-06 7.3026E-07 0.037241"
        rpy="0 0 0" />
      <mass
        value="1" />
      <inertia
        ixx="1"
        ixy="1"
        ixz="1"
        iyy="1"
        iyz="1"
        izz="1" />
    </inertial>
    <visual>
      <origin
        xyz="0 0 0"
        rpy="0 0 0" />
      <geometry>
        <mesh
          filename="package://omni_robot/meshes/Wheel_Back_Right.STL" />
      </geometry>
      <material
        name="">
        <color
          rgba="0.69804 0.69804 0.69804 1" />
      </material>
    </visual>
    <collision>
      <origin
        xyz="0 0 0"
        rpy="0 0 0" />
      <geometry>
        <mesh
          filename="package://omni_robot/meshes/Wheel_Back_Right.STL" />
      </geometry>
    </collision>
  </link>
  <joint
    name="joint_wbr"
    type="continuous">
    <origin
      xyz="-0.0417178615723627 -0.015 -0.0417163514583423"
      rpy="-2.53945491963175 -0.539418716969584 2.21259820634418" />
    <parent
      link="base_link" />
    <child
      link="Wheel_Back_Right" />
    <axis
      xyz="0 0 1" />
  </joint>
  <link
    name="Wheel_secondary_bl1">
    <inertial>
      <origin
        xyz="-2.7864E-17 0 3.4694E-18"
        rpy="0 0 0" />
      <mass
        value="0.0012665" />
      <inertia
        ixx="0"
        ixy="0"
        ixz="0"
        iyy="0"
        iyz="0"
        izz="0" />
    </inertial>
    <visual>
      <origin
        xyz="0 0 0"
        rpy="0 0 0" />
      <geometry>
        <mesh
          filename="package://omni_robot/meshes/Wheel_secondary_bl1.STL" />
      </geometry>
      <material
        name="">
        <color
          rgba="0.69804 0.69804 0.69804 1" />
      </material>
    </visual>
    <collision>
      <origin
        xyz="0 0 0"
        rpy="0 0 0" />
      <geometry>
        <mesh
          filename="package://omni_robot/meshes/Wheel_secondary_bl1.STL" />
      </geometry>
    </collision>
  </link>
  <joint
    name="joint_wsbl1"
    type="continuous">
    <origin
      xyz="-0.0094642 -0.0094599 0.043736"
      rpy="-1.5969 0 2.3577" />
    <parent
      link="Wheel_Back_Right" />
    <child
      link="Wheel_secondary_bl1" />
    <axis
      xyz="-1 0 0" />
  </joint>
  <link
    name="Wheel_secondary_bl2">
    <inertial>
      <origin
        xyz="-8.6736E-18 0 0"
        rpy="0 0 0" />
      <mass
        value="0.0012665" />
      <inertia
        ixx="0"
        ixy="0"
        ixz="0"
        iyy="0"
        iyz="0"
        izz="0" />
    </inertial>
    <visual>
      <origin
        xyz="0 0 0"
        rpy="0 0 0" />
      <geometry>
        <mesh
          filename="package://omni_robot/meshes/Wheel_secondary_bl2.STL" />
      </geometry>
      <material
        name="">
        <color
          rgba="0.69804 0.69804 0.69804 1" />
      </material>
    </visual>
    <collision>
      <origin
        xyz="0 0 0"
        rpy="0 0 0" />
      <geometry>
        <mesh
          filename="package://omni_robot/meshes/Wheel_secondary_bl2.STL" />
      </geometry>
    </collision>
  </link>
  <joint
    name="joint_wsbl2"
    type="continuous">
    <origin
      xyz="0.009453 -0.009453 0.043736"
      rpy="-0.78559 0 -2.3562" />
    <parent
      link="Wheel_Back_Right" />
    <child
      link="Wheel_secondary_bl2" />
    <axis
      xyz="-1 0 0" />
  </joint>
  <link
    name="Wheel_secondary_bl3">
    <inertial>
      <origin
        xyz="2.0817E-17 0 6.5052E-19"
        rpy="0 0 0" />
      <mass
        value="0.0012665" />
      <inertia
        ixx="0"
        ixy="0"
        ixz="0"
        iyy="0"
        iyz="0"
        izz="0" />
    </inertial>
    <visual>
      <origin
        xyz="0 0 0"
        rpy="0 0 0" />
      <geometry>
        <mesh
          filename="package://omni_robot/meshes/Wheel_secondary_bl3.STL" />
      </geometry>
      <material
        name="">
        <color
          rgba="0.69804 0.69804 0.69804 1" />
      </material>
    </visual>
    <collision>
      <origin
        xyz="0 0 0"
        rpy="0 0 0" />
      <geometry>
        <mesh
          filename="package://omni_robot/meshes/Wheel_secondary_bl3.STL" />
      </geometry>
    </collision>
  </link>
  <joint
    name="joint_wsbl3"
    type="continuous">
    <origin
      xyz="0.0094129 0.009475 0.043736"
      rpy="-1.5447 0 -0.78387" />
    <parent
      link="Wheel_Back_Right" />
    <child
      link="Wheel_secondary_bl3" />
    <axis
      xyz="1 0 0" />
  </joint>
  <link
    name="Wheel_secondary_bl4">
    <inertial>
      <origin
        xyz="-1.3878E-17 0 0"
        rpy="0 0 0" />
      <mass
        value="0.0012665" />
      <inertia
        ixx="0"
        ixy="0"
        ixz="0"
        iyy="0"
        iyz="0"
        izz="0" />
    </inertial>
    <visual>
      <origin
        xyz="0 0 0"
        rpy="0 0 0" />
      <geometry>
        <mesh
          filename="package://omni_robot/meshes/Wheel_secondary_bl4.STL" />
      </geometry>
      <material
        name="">
        <color
          rgba="0.69804 0.69804 0.69804 1" />
      </material>
    </visual>
    <collision>
      <origin
        xyz="0 0 0"
        rpy="0 0 0" />
      <geometry>
        <mesh
          filename="package://omni_robot/meshes/Wheel_secondary_bl4.STL" />
      </geometry>
    </collision>
  </link>
  <joint
    name="joint_wsbl4"
    type="continuous">
    <origin
      xyz="-0.009453 0.009453 0.043736"
      rpy="-0.78559 0 -2.3562" />
    <parent
      link="Wheel_Back_Right" />
    <child
      link="Wheel_secondary_bl4" />
    <axis
      xyz="-1 0 0" />
  </joint>
  <link
    name="Wheel_secondary_bl5">
    <inertial>
      <origin
        xyz="1.3878E-17 0 0"
        rpy="0 0 0" />
      <mass
        value="0.0012665" />
      <inertia
        ixx="0"
        ixy="0"
        ixz="0"
        iyy="0"
        iyz="0"
        izz="0" />
    </inertial>
    <visual>
      <origin
        xyz="0 0 0"
        rpy="0 0 0" />
      <geometry>
        <mesh
          filename="package://omni_robot/meshes/Wheel_secondary_bl5.STL" />
      </geometry>
      <material
        name="">
        <color
          rgba="0.69804 0.69804 0.69804 1" />
      </material>
    </visual>
    <collision>
      <origin
        xyz="0 0 0"
        rpy="0 0 0" />
      <geometry>
        <mesh
          filename="package://omni_robot/meshes/Wheel_secondary_bl5.STL" />
      </geometry>
    </collision>
  </link>
  <joint
    name="joint_wsbl5"
    type="continuous">
    <origin
      xyz="-0.013369 0 0.030736"
      rpy="-0.94258 0 -1.5708" />
    <parent
      link="Wheel_Back_Right" />
    <child
      link="Wheel_secondary_bl5" />
    <axis
      xyz="1 0 0" />
  </joint>
  <link
    name="Wheel_secondary_bl6">
    <inertial>
      <origin
        xyz="-1.2143E-17 0 6.9389E-18"
        rpy="0 0 0" />
      <mass
        value="0.0012665" />
      <inertia
        ixx="0"
        ixy="0"
        ixz="0"
        iyy="0"
        iyz="0"
        izz="0" />
    </inertial>
    <visual>
      <origin
        xyz="0 0 0"
        rpy="0 0 0" />
      <geometry>
        <mesh
          filename="package://omni_robot/meshes/Wheel_secondary_bl6.STL" />
      </geometry>
      <material
        name="">
        <color
          rgba="0.69804 0.69804 0.69804 1" />
      </material>
    </visual>
    <collision>
      <origin
        xyz="0 0 0"
        rpy="0 0 0" />
      <geometry>
        <mesh
          filename="package://omni_robot/meshes/Wheel_secondary_bl6.STL" />
      </geometry>
    </collision>
  </link>
  <joint
    name="joint_wsbl6"
    type="continuous">
    <origin
      xyz="0 0.013369 0.030736"
      rpy="-0.96866 0 -3.1416" />
    <parent
      link="Wheel_Back_Right" />
    <child
      link="Wheel_secondary_bl6" />
    <axis
      xyz="-1 0 0" />
  </joint>
  <link
    name="Wheel_secondary_bl7">
    <inertial>
      <origin
        xyz="-1.0408E-17 0 0"
        rpy="0 0 0" />
      <mass
        value="0.0012665" />
      <inertia
        ixx="0"
        ixy="0"
        ixz="0"
        iyy="0"
        iyz="0"
        izz="0" />
    </inertial>
    <visual>
      <origin
        xyz="0 0 0"
        rpy="0 0 0" />
      <geometry>
        <mesh
          filename="package://omni_robot/meshes/Wheel_secondary_bl7.STL" />
      </geometry>
      <material
        name="">
        <color
          rgba="0.69804 0.69804 0.69804 1" />
      </material>
    </visual>
    <collision>
      <origin
        xyz="0 0 0"
        rpy="0 0 0" />
      <geometry>
        <mesh
          filename="package://omni_robot/meshes/Wheel_secondary_bl7.STL" />
      </geometry>
    </collision>
  </link>
  <joint
    name="joint_wsbl7"
    type="continuous">
    <origin
      xyz="0.013369 0 0.030736"
      rpy="-2.199 0 1.5708" />
    <parent
      link="Wheel_Back_Right" />
    <child
      link="Wheel_secondary_bl7" />
    <axis
      xyz="-1 0 0" />
  </joint>
  <link
    name="Wheel_secondary_bl8">
    <inertial>
      <origin
        xyz="1.3878E-17 2.7756E-17 0"
        rpy="0 0 0" />
      <mass
        value="0.0012665" />
      <inertia
        ixx="0"
        ixy="0"
        ixz="0"
        iyy="0"
        iyz="0"
        izz="0" />
    </inertial>
    <visual>
      <origin
        xyz="0 0 0"
        rpy="0 0 0" />
      <geometry>
        <mesh
          filename="package://omni_robot/meshes/Wheel_secondary_bl8.STL" />
      </geometry>
      <material
        name="">
        <color
          rgba="0.69804 0.69804 0.69804 1" />
      </material>
    </visual>
    <collision>
      <origin
        xyz="0 0 0"
        rpy="0 0 0" />
      <geometry>
        <mesh
          filename="package://omni_robot/meshes/Wheel_secondary_bl8.STL" />
      </geometry>
    </collision>
  </link>
  <joint
    name="joint_wsbl8"
    type="continuous">
    <origin
      xyz="0 -0.013369 0.030736"
      rpy="-2.1729 0 0" />
    <parent
      link="Wheel_Back_Right" />
    <child
      link="Wheel_secondary_bl8" />
    <axis
      xyz="1 0 0" />
  </joint>
  <link
    name="Wheel_Back_Left">
    <inertial>
      <origin
        xyz="7.1108E-06 7.3033E-07 4.8029E-06"
        rpy="0 0 0" />
      <mass
        value="1" />
      <inertia
        ixx="1"
        ixy="1"
        ixz="1"
        iyy="1"
        iyz="1"
        izz="1" />
    </inertial>
    <visual>
      <origin
        xyz="0 0 0"
        rpy="0 0 0" />
      <geometry>
        <mesh
          filename="package://omni_robot/meshes/Wheel_Back_Left.STL" />
      </geometry>
      <material
        name="">
        <color
          rgba="0.69804 0.69804 0.69804 1" />
      </material>
    </visual>
    <collision>
      <origin
        xyz="0 0 0"
        rpy="0 0 0" />
      <geometry>
        <mesh
          filename="package://omni_robot/meshes/Wheel_Back_Left.STL" />
      </geometry>
    </collision>
  </link>
  <joint
    name="joint_wbl"
    type="continuous">
    <origin
      xyz="0.0679383724215803 -0.015 -0.0680478080311934"
      rpy="2.53568356299813 0.535049800440287 2.20522888954119" />
    <parent
      link="base_link" />
    <child
      link="Wheel_Back_Left" />
    <axis
      xyz="0 0 1" />
  </joint>
  <link
    name="Wheel_secondary_br1">
    <inertial>
      <origin
        xyz="-2.0318E-16 1.249E-16 1.0061E-16"
        rpy="0 0 0" />
      <mass
        value="0.0012665" />
      <inertia
        ixx="0"
        ixy="0"
        ixz="0"
        iyy="0"
        iyz="0"
        izz="0" />
    </inertial>
    <visual>
      <origin
        xyz="0 0 0"
        rpy="0 0 0" />
      <geometry>
        <mesh
          filename="package://omni_robot/meshes/Wheel_secondary_br1.STL" />
      </geometry>
      <material
        name="">
        <color
          rgba="0.69804 0.69804 0.69804 1" />
      </material>
    </visual>
    <collision>
      <origin
        xyz="0 0 0"
        rpy="0 0 0" />
      <geometry>
        <mesh
          filename="package://omni_robot/meshes/Wheel_secondary_br1.STL" />
      </geometry>
    </collision>
  </link>
  <joint
    name="joint_wsbr1"
    type="continuous">
    <origin
      xyz="-0.0094642 -0.0094599 0.0065"
      rpy="-1.5524 0 2.3577" />
    <parent
      link="Wheel_Back_Left" />
    <child
      link="Wheel_secondary_br1" />
    <axis
      xyz="-1 0 0" />
  </joint>
  <link
    name="Wheel_secondary_br2">
    <inertial>
      <origin
        xyz="-9.541E-17 -6.9389E-17 -2.3592E-16"
        rpy="0 0 0" />
      <mass
        value="0.0012665" />
      <inertia
        ixx="0"
        ixy="0"
        ixz="0"
        iyy="0"
        iyz="0"
        izz="0" />
    </inertial>
    <visual>
      <origin
        xyz="0 0 0"
        rpy="0 0 0" />
      <geometry>
        <mesh
          filename="package://omni_robot/meshes/Wheel_secondary_br2.STL" />
      </geometry>
      <material
        name="">
        <color
          rgba="0.69804 0.69804 0.69804 1" />
      </material>
    </visual>
    <collision>
      <origin
        xyz="0 0 0"
        rpy="0 0 0" />
      <geometry>
        <mesh
          filename="package://omni_robot/meshes/Wheel_secondary_br2.STL" />
      </geometry>
    </collision>
  </link>
  <joint
    name="joint_wsbr2"
    type="continuous">
    <origin
      xyz="-0.009453 0.009453 0.0065"
      rpy="-0.7855 0 0.7854" />
    <parent
      link="Wheel_Back_Left" />
    <child
      link="Wheel_secondary_br2" />
    <axis
      xyz="1 0 0" />
  </joint>
  <link
    name="Wheel_secondary_br3">
    <inertial>
      <origin
        xyz="2.1711E-16 1.249E-16 -1.0322E-16"
        rpy="0 0 0" />
      <mass
        value="0.0012665" />
      <inertia
        ixx="0"
        ixy="0"
        ixz="0"
        iyy="0"
        iyz="0"
        izz="0" />
    </inertial>
    <visual>
      <origin
        xyz="0 0 0"
        rpy="0 0 0" />
      <geometry>
        <mesh
          filename="package://omni_robot/meshes/Wheel_secondary_br3.STL" />
      </geometry>
      <material
        name="">
        <color
          rgba="0.69804 0.69804 0.69804 1" />
      </material>
    </visual>
    <collision>
      <origin
        xyz="0 0 0"
        rpy="0 0 0" />
      <geometry>
        <mesh
          filename="package://omni_robot/meshes/Wheel_secondary_br3.STL" />
      </geometry>
    </collision>
  </link>
  <joint
    name="joint_wsbr3"
    type="continuous">
    <origin
      xyz="0.0094129 0.009475 0.0065"
      rpy="-1.5892 0 -0.78387" />
    <parent
      link="Wheel_Back_Left" />
    <child
      link="Wheel_secondary_br3" />
    <axis
      xyz="1 0 0" />
  </joint>
  <link
    name="Wheel_secondary_br4">
    <inertial>
      <origin
        xyz="9.7145E-17 -6.9389E-17 2.2204E-16"
        rpy="0 0 0" />
      <mass
        value="0.0012665" />
      <inertia
        ixx="0"
        ixy="0"
        ixz="0"
        iyy="0"
        iyz="0"
        izz="0" />
    </inertial>
    <visual>
      <origin
        xyz="0 0 0"
        rpy="0 0 0" />
      <geometry>
        <mesh
          filename="package://omni_robot/meshes/Wheel_secondary_br4.STL" />
      </geometry>
      <material
        name="">
        <color
          rgba="0.69804 0.69804 0.69804 1" />
      </material>
    </visual>
    <collision>
      <origin
        xyz="0 0 0"
        rpy="0 0 0" />
      <geometry>
        <mesh
          filename="package://omni_robot/meshes/Wheel_secondary_br4.STL" />
      </geometry>
    </collision>
  </link>
  <joint
    name="joint_wsbr4"
    type="continuous">
    <origin
      xyz="0.009453 -0.009453 0.0065"
      rpy="-2.3561 0 -2.3562" />
    <parent
      link="Wheel_Back_Left" />
    <child
      link="Wheel_secondary_br4" />
    <axis
      xyz="-1 0 0" />
  </joint>
  <link
    name="Wheel_secondary_br5">
    <inertial>
      <origin
        xyz="2.2551E-16 4.8572E-17 1.1102E-16"
        rpy="0 0 0" />
      <mass
        value="0.0012665" />
      <inertia
        ixx="0"
        ixy="0"
        ixz="0"
        iyy="0"
        iyz="0"
        izz="0" />
    </inertial>
    <visual>
      <origin
        xyz="0 0 0"
        rpy="0 0 0" />
      <geometry>
        <mesh
          filename="package://omni_robot/meshes/Wheel_secondary_br5.STL" />
      </geometry>
      <material
        name="">
        <color
          rgba="0.69804 0.69804 0.69804 1" />
      </material>
    </visual>
    <collision>
      <origin
        xyz="0 0 0"
        rpy="0 0 0" />
      <geometry>
        <mesh
          filename="package://omni_robot/meshes/Wheel_secondary_br5.STL" />
      </geometry>
    </collision>
  </link>
  <joint
    name="joint_wsbr5"
    type="continuous">
    <origin
      xyz="-0.013369 0 -0.0065"
      rpy="-2.1955 0 -1.5708" />
    <parent
      link="Wheel_Back_Left" />
    <child
      link="Wheel_secondary_br5" />
    <axis
      xyz="1 0 0" />
  </joint>
  <link
    name="Wheel_secondary_br6">
    <inertial>
      <origin
        xyz="-1.0408E-17 1.3878E-17 1.3878E-17"
        rpy="0 0 0" />
      <mass
        value="0.0012665" />
      <inertia
        ixx="0"
        ixy="0"
        ixz="0"
        iyy="0"
        iyz="0"
        izz="0" />
    </inertial>
    <visual>
      <origin
        xyz="0 0 0"
        rpy="0 0 0" />
      <geometry>
        <mesh
          filename="package://omni_robot/meshes/Wheel_secondary_br6.STL" />
      </geometry>
      <material
        name="">
        <color
          rgba="0.69804 0.69804 0.69804 1" />
      </material>
    </visual>
    <collision>
      <origin
        xyz="0 0 0"
        rpy="0 0 0" />
      <geometry>
        <mesh
          filename="package://omni_robot/meshes/Wheel_secondary_br6.STL" />
      </geometry>
    </collision>
  </link>
  <joint
    name="joint_wsbr6"
    type="continuous">
    <origin
      xyz="0 0.013369 -0.0065"
      rpy="-2.1767 0 3.1416" />
    <parent
      link="Wheel_Back_Left" />
    <child
      link="Wheel_secondary_br6" />
    <axis
      xyz="-1 0 0" />
  </joint>
  <link
    name="Wheel_secondary_br7">
    <inertial>
      <origin
        xyz="-1.3878E-17 -1.3878E-17 0"
        rpy="0 0 0" />
      <mass
        value="0.0012665" />
      <inertia
        ixx="0"
        ixy="0"
        ixz="0"
        iyy="0"
        iyz="0"
        izz="0" />
    </inertial>
    <visual>
      <origin
        xyz="0 0 0"
        rpy="0 0 0" />
      <geometry>
        <mesh
          filename="package://omni_robot/meshes/Wheel_secondary_br7.STL" />
      </geometry>
      <material
        name="">
        <color
          rgba="0.69804 0.69804 0.69804 1" />
      </material>
    </visual>
    <collision>
      <origin
        xyz="0 0 0"
        rpy="0 0 0" />
      <geometry>
        <mesh
          filename="package://omni_robot/meshes/Wheel_secondary_br7.STL" />
      </geometry>
    </collision>
  </link>
  <joint
    name="joint_wsbr7"
    type="continuous">
    <origin
      xyz="0.013369 0 -0.0065"
      rpy="-0.94606 0 1.5708" />
    <parent
      link="Wheel_Back_Left" />
    <child
      link="Wheel_secondary_br7" />
    <axis
      xyz="-1 0 0" />
  </joint>
  <link
    name="Wheel_secondary_br8">
    <inertial>
      <origin
        xyz="1.3878E-17 1.3878E-17 -1.0408E-17"
        rpy="0 0 0" />
      <mass
        value="0.0012665" />
      <inertia
        ixx="0"
        ixy="0"
        ixz="0"
        iyy="0"
        iyz="0"
        izz="0" />
    </inertial>
    <visual>
      <origin
        xyz="0 0 0"
        rpy="0 0 0" />
      <geometry>
        <mesh
          filename="package://omni_robot/meshes/Wheel_secondary_br8.STL" />
      </geometry>
      <material
        name="">
        <color
          rgba="0.69804 0.69804 0.69804 1" />
      </material>
    </visual>
    <collision>
      <origin
        xyz="0 0 0"
        rpy="0 0 0" />
      <geometry>
        <mesh
          filename="package://omni_robot/meshes/Wheel_secondary_br8.STL" />
      </geometry>
    </collision>
  </link>
  <joint
    name="joint_wsbr8"
    type="continuous">
    <origin
      xyz="0 -0.013369 -0.0065"
      rpy="-0.96489 0 0" />
    <parent
      link="Wheel_Back_Left" />
    <child
      link="Wheel_secondary_br8" />
    <axis
      xyz="1 0 0" />
  </joint>
  <link
    name="Puncher">
    <inertial>
      <origin
        xyz="1.4818E-06 3.7492E-06 0.022357"
        rpy="0 0 0" />
      <mass
        value="0.028806" />
      <inertia
        ixx="0"
        ixy="0"
        ixz="0"
        iyy="0"
        iyz="0"
        izz="0" />
    </inertial>
    <visual>
      <origin
        xyz="0 0 0"
        rpy="0 0 0" />
      <geometry>
        <mesh
          filename="package://omni_robot/meshes/Puncher.STL" />
      </geometry>
      <material
        name="">
        <color
          rgba="0.52941 0.54902 0.54902 1" />
      </material>
    </visual>
    <collision>
      <origin
        xyz="0 0 0"
        rpy="0 0 0" />
      <geometry>
        <mesh
          filename="package://omni_robot/meshes/Puncher.STL" />
      </geometry>
    </collision>
  </link>
  <joint
    name="joint_puncher"
    type="continuous">
    <origin
      xyz="0 -0.015 0.0425"
      rpy="0 0 -1.1944" />
    <parent
      link="base_link" />
    <child
      link="Puncher" />
    <axis
      xyz="0 0 1" />
  </joint>
  <link
    name="Dribler">
    <inertial>
      <origin
        xyz="-2.4547E-05 -6.3304E-05 -4.1744E-06"
        rpy="0 0 0" />
      <mass
        value="0.01841" />
      <inertia
        ixx="0"
        ixy="0"
        ixz="0"
        iyy="0"
        iyz="0"
        izz="0" />
    </inertial>
    <visual>
      <origin
        xyz="0 0 0"
        rpy="0 0 0" />
      <geometry>
        <mesh
          filename="package://omni_robot/meshes/Dribler.STL" />
      </geometry>
      <material
        name="">
        <color
          rgba="0.52941 0.54902 0.54902 1" />
      </material>
    </visual>
    <collision>
      <origin
        xyz="0 0 0"
        rpy="0 0 0" />
      <geometry>
        <mesh
          filename="package://omni_robot/meshes/Dribler.STL" />
      </geometry>
    </collision>
  </link>
  <joint
    name="joint_dribler"
    type="continuous">
    <origin
      xyz="0 -0.033 0.07625"
      rpy="-1.5708 0.054033 1.5708" />
    <parent
      link="base_link" />
    <child
      link="Dribler" />
    <axis
      xyz="-1 0 0" />
  </joint>
  <link
    name="Camera">
    <inertial>
      <origin
        xyz="0 0 0"
        rpy="0 0 0" />
      <mass
        value="0" />
      <inertia
        ixx="0"
        ixy="0"
        ixz="0"
        iyy="0"
        iyz="0"
        izz="0" />
    </inertial>
    <visual>
      <origin
        xyz="0 0 0"
        rpy="0 0 0" />
      <geometry>
        <mesh
          filename="package://omni_robot/meshes/Camera.STL" />
      </geometry>
      <material
        name="">
        <color
          rgba="1 1 1 1" />
      </material>
    </visual>
    <collision>
      <origin
        xyz="0 0 0"
        rpy="0 0 0" />
      <geometry>
        <mesh
          filename="package://omni_robot/meshes/Camera.STL" />
      </geometry>
    </collision>
  </link>
  <joint
    name="joint_camera"
    type="fixed">
    <origin
      xyz="-0.000578757343717447 -0.045 0.075"
      rpy="3.14 -1.57080 0" />
    <parent
      link="base_link" />
    <child
      link="Camera" />
    <axis
      xyz="0 0 0" />
  </joint>
  <link
    name="Laser">
    <inertial>
      <origin
        xyz="0.005 0 0.0025"
        rpy="0 0 0" />
      <mass
        value="0.00072471" />
      <inertia
        ixx="0"
        ixy="0"
        ixz="0"
        iyy="0"
        iyz="0"
        izz="0" />
    </inertial>
    <visual>
      <origin
        xyz="0 0 0"
        rpy="0 0 0" />
      <geometry>
        <mesh
          filename="package://omni_robot/meshes/Laser.STL" />
      </geometry>
      <material
        name="">
        <color
          rgba="0.69804 0.69804 0.69804 1" />
      </material>
    </visual>
    <collision>
      <origin
        xyz="0 0 0"
        rpy="0 0 0" />
      <geometry>
        <mesh
          filename="package://omni_robot/meshes/Laser.STL" />
      </geometry>
    </collision>
  </link>
  <joint
    name="joint_laser"
    type="fixed">
    <origin
      xyz="-0.005 -0.04 0.07"
      rpy="1.57 0 0" />
    <parent
      link="base_link" />
    <child
      link="Laser" />
    <axis
      xyz="1 0 0" />
  </joint>

  <gazebo reference="Laser">
			<sensor type="ray" name="head_hokuyo_sensor">
				<pose>0 0 0 0 0 0</pose>
				<visualize>false</visualize>
				<update_rate>40</update_rate>
				<ray>
					<scan>
						<horizontal>
							<samples>720</samples>
							<resolution>1</resolution>
							<min_angle>-1.570796</min_angle>
							<max_angle>1.570796</max_angle>
						</horizontal>
					</scan>
					<range>
						<min>0.10</min>
						<max>30.0</max>
						<resolution>0.01</resolution>
					</range>
					<noise>
						<type>gaussian</type>
						<mean>0.0</mean>
						<stddev>0.01</stddev>
					</noise>
				</ray>

				<plugin name="gazebo_ros_head_hokuyo_controller" filename="libgazebo_ros_laser.so">
					<topicName>/waze/laser/scan</topicName>
					<frameName>sensor_laser</frameName>
			    </plugin>
			</sensor>
 	 	</gazebo>

  <gazebo>
    <plugin name="gazebo_ros_control" filename="libgazebo_ros_control.so">
      <robotNamespace>omni_robot</robotNamespace>
    </plugin>
  </gazebo>

  <gazebo reference="Camera">
      <sensor type="camera" name="camera_bot">
        <update_rate>30.0</update_rate>
        <camera name="head">
          <horizontal_fov>1.3962634</horizontal_fov>
          <image>
            <width>800</width>
            <height>800</height>
            <format>R8G8B8</format>
          </image>
          <clip>
            <near>0.02</near>
            <far>300</far>
          </clip>
          <noise>
            <type>gaussian</type>
            <mean>0.0</mean>
            <stddev>0.007</stddev>
          </noise>
        </camera>
        <plugin name="camera_controller" filename="libgazebo_ros_camera.so">
          <alwaysOn>true</alwaysOn>
          <updateRate>0.0</updateRate>
          <cameraName>omni_robot/camera_bot</cameraName>
          <imageTopicName>image_raw</imageTopicName>
          <cameraInfoTopicName>camera_info</cameraInfoTopicName>
          <frameName>Camera_Frame</frameName>
          <hackBaseline>0.07</hackBaseline>
          <distortionK1>0.0</distortionK1>
          <distortionK2>0.0</distortionK2>
          <distortionK3>0.0</distortionK3>
          <distortionT1>0.0</distortionT1>
          <distortionT2>0.0</distortionT2>
        </plugin>
      </sensor>
    </gazebo>

  <transmission name="wfl_trans" type="SimpleTransmission">
    <type>transmission_interface/SimpleTransmission</type>
    <actuator name="wfl_motor">
      <mechanicalReduction>1</mechanicalReduction>
    </actuator>
    <joint name="joint_wfl">
      <hardwareInterface>hardware_interface/VelocityJointInterface</hardwareInterface>
    </joint>
  </transmission>
  
  <transmission name="wfr_trans" type="SimpleTransmission">
    <type>transmission_interface/SimpleTransmission</type>
    <actuator name="wfr_motor">
      <mechanicalReduction>1</mechanicalReduction>
    </actuator>
    <joint name="joint_wfr">
      <hardwareInterface>hardware_interface/VelocityJointInterface</hardwareInterface>
    </joint>
  </transmission>
  
  <transmission name="wbl_trans" type="SimpleTransmission">
    <type>transmission_interface/SimpleTransmission</type>
    <actuator name="wbl_motor">
      <mechanicalReduction>1</mechanicalReduction>
    </actuator>
    <joint name="joint_wbl">
      <hardwareInterface>hardware_interface/VelocityJointInterface</hardwareInterface>
    </joint>
  </transmission>

  <transmission name="wbr_trans" type="SimpleTransmission">
    <type>transmission_interface/SimpleTransmission</type>
    <actuator name="wbr_motor">
      <mechanicalReduction>1</mechanicalReduction>
    </actuator>
    <joint name="joint_wbr">
      <hardwareInterface>hardware_interface/VelocityJointInterface</hardwareInterface>
    </joint>
  </transmission>

  <transmission name="dribler_trans" type="SimpleTransmission">
    <type>transmission_interface/SimpleTransmission</type>
    <actuator name="dribler_motor">
      <mechanicalReduction>1</mechanicalReduction>
    </actuator>
    <joint name="joint_dribler">
      <hardwareInterface>hardware_interface/VelocityJointInterface</hardwareInterface>
    </joint>
  </transmission>

  <transmission name="puncher_trans" type="SimpleTransmission">
    <type>transmission_interface/SimpleTransmission</type>
    <actuator name="puncher_solenoid">
      <mechanicalReduction>1</mechanicalReduction>
    </actuator>
    <joint name="joint_puncher">
      <hardwareInterface>hardware_interface/EffortJointInterface</hardwareInterface>
    </joint>
  </transmission>

</robot>