<?xml version="1.0" encoding="utf-8"?>
<!-- This URDF was automatically created by SolidWorks to URDF Exporter! Originally created by Stephen Brawner (brawner@gmail.com) 
     Commit Version: 1.6.0-1-g15f4949  Build Version: 1.6.7594.29634
     For more information, please see http://wiki.ros.org/sw_urdf_exporter -->
<robot
  name="omni_robot">
  <link
    name="base_link">
    <inertial>
      <origin
        xyz="-9.13611639294152E-05 0.00214232217806076 0.0214319897115358"
        rpy="0 0 0" />
      <mass
        value="0.852809673697343" />
      <inertia
        ixx="0."
        ixy="0"
        ixz="0"
        iyy="0"
        iyz="0"
        izz="0" />
    </inertial>
    <visual>
      <origin
        xyz="0 0 0"
        rpy="0 0 0" />
      <geometry>
        <mesh
          filename="package://omni_robot/meshes/base_link.STL" />
      </geometry>
      <material
        name="">
        <color
          rgba="0.698039215686274 0.698039215686274 0.698039215686274 1" />
      </material>
    </visual>
    <collision>
      <origin
        xyz="0 0 0"
        rpy="0 0 0" />
      <geometry>
        <mesh
          filename="package://omni_robot/meshes/base_link.STL" />
      </geometry>
    </collision>
  </link>
  <link
    name="Wheel_Front_Right">
    <inertial>
      <origin
        xyz="-0.0131020286356422 -1.20155560002361E-06 6.56261469429362E-07"
        rpy="0 0 0" />
      <mass
        value="0.0200704573599485" />
      <inertia
        ixx="0."
        ixy="0"
        ixz="0"
        iyy="0"
        iyz="0"
        izz="0" />
    </inertial>
    <visual>
      <origin
        xyz="0 0 0"
        rpy="0 0 0" />
      <geometry>
        <mesh
          filename="package://omni_robot/meshes/Wheel_Front_Right.STL" />
      </geometry>
      <material
        name="">
        <color
          rgba="0.752941176470588 0.752941176470588 0.752941176470588 1" />
      </material>
    </visual>
    <collision>
      <origin
        xyz="0 0 0"
        rpy="0 0 0" />
      <geometry>
        <mesh
          filename="package://omni_robot/meshes/Wheel_Front_Right.STL" />
      </geometry>
    </collision>
  </link>
  <joint
    name="joint_wfr"
    type="continuous">
    <origin
      xyz="0.0760716105192469 0.076070100405225 0.0149999999999999"
      rpy="0 0 0.785398163397451" />
    <parent
      link="base_link" />
    <child
      link="Wheel_Front_Right" />
    <axis
      xyz="1 0 0" />
  </joint>
  <link
    name="Wheel_Front_Left">
    <inertial>
      <origin
        xyz="-0.0131020440662054 5.27333704342103E-07 -1.26179584825949E-06"
        rpy="0 0 0" />
      <mass
        value="0.0200704541706871" />
      <inertia
        ixx="0."
        ixy="0"
        ixz="0"
        iyy="0"
        iyz="0"
        izz="0" />
    </inertial>
    <visual>
      <origin
        xyz="0 0 0"
        rpy="0 0 0" />
      <geometry>
        <mesh
          filename="package://omni_robot/meshes/Wheel_Front_Left.STL" />
      </geometry>
      <material
        name="">
        <color
          rgba="0.752941176470588 0.752941176470588 0.752941176470588 1" />
      </material>
    </visual>
    <collision>
      <origin
        xyz="0 0 0"
        rpy="0 0 0" />
      <geometry>
        <mesh
          filename="package://omni_robot/meshes/Wheel_Front_Left.STL" />
      </geometry>
    </collision>
  </link>
  <joint
    name="joint_wfl"
    type="continuous">
    <origin
      xyz="-0.0761780259008162 0.0760716105192465 0.0149999999999998"
      rpy="0 0 2.35619449019235" />
    <parent
      link="base_link" />
    <child
      link="Wheel_Front_Left" />
    <axis
      xyz="1 0 0" />
  </joint>
  <link
    name="Wheel_Back_Left">
    <inertial>
      <origin
        xyz="-0.0131020287152041 1.22305777813109E-06 -6.15396704395713E-07"
        rpy="0 0 0" />
      <mass
        value="0.0200704384003013" />
      <inertia
        ixx="0."
        ixy="0"
        ixz="0"
        iyy="0"
        iyz="0"
        izz="0" />
    </inertial>
    <visual>
      <origin
        xyz="0 0 0"
        rpy="0 0 0" />
      <geometry>
        <mesh
          filename="package://omni_robot/meshes/Wheel_Back_Left.STL" />
      </geometry>
      <material
        name="">
        <color
          rgba="0.752941176470588 0.752941176470588 0.752941176470588 1" />
      </material>
    </visual>
    <collision>
      <origin
        xyz="0 0 0"
        rpy="0 0 0" />
      <geometry>
        <mesh
          filename="package://omni_robot/meshes/Wheel_Back_Left.STL" />
      </geometry>
    </collision>
  </link>
  <joint
    name="joint_wbl"
    type="continuous">
    <origin
      xyz="-0.0761795360148377 -0.0761780259008174 0.015"
      rpy="0 0 -2.35619449019234" />
    <parent
      link="base_link" />
    <child
      link="Wheel_Back_Left" />
    <axis
      xyz="1 0 0" />
  </joint>
  <link
    name="Wheel_Back_Right">
    <inertial>
      <origin
        xyz="-0.0131020468480355 6.55532774979095E-07 -1.19984742866404E-06"
        rpy="0 0 0" />
      <mass
        value="0.0200704565850667" />
      <inertia
        ixx="0."
        ixy="0"
        ixz="0"
        iyy="0"
        iyz="0"
        izz="0" />
    </inertial>
    <visual>
      <origin
        xyz="0 0 0"
        rpy="0 0 0" />
      <geometry>
        <mesh
          filename="package://omni_robot/meshes/Wheel_Back_Right.STL" />
      </geometry>
      <material
        name="">
        <color
          rgba="0.752941176470588 0.752941176470588 0.752941176470588 1" />
      </material>
    </visual>
    <collision>
      <origin
        xyz="0 0 0"
        rpy="0 0 0" />
      <geometry>
        <mesh
          filename="package://omni_robot/meshes/Wheel_Back_Right.STL" />
      </geometry>
    </collision>
  </link>
  <joint
    name="joint_wbr"
    type="continuous">
    <origin
      xyz="0.0760701004052256 -0.0761795360148388 0.015"
      rpy="0 0 -0.785398163397447" />
    <parent
      link="base_link" />
    <child
      link="Wheel_Back_Right" />
    <axis
      xyz="1 0 0" />
  </joint>
  <link
    name="Dribler">
    <inertial>
      <origin
        xyz="0.0357501429792025 6.45374790612246E-05 2.10955274688868E-05"
        rpy="0 0 0" />
      <mass
        value="0.0184095355673453" />
      <inertia
        ixx="0."
        ixy="0"
        ixz="0"
        iyy="0"
        iyz="0"
        izz="0" />
    </inertial>
    <visual>
      <origin
        xyz="0 0 0"
        rpy="0 0 0" />
      <geometry>
        <mesh
          filename="package://omni_robot/meshes/Dribler.STL" />
      </geometry>
      <material
        name="">
        <color
          rgba="0.529411764705882 0.549019607843137 0.549019607843137 1" />
      </material>
    </visual>
    <collision>
      <origin
        xyz="0 0 0"
        rpy="0 0 0" />
      <geometry>
        <mesh
          filename="package://omni_robot/meshes/Dribler.STL" />
      </geometry>
    </collision>
  </link>
  <joint
    name="joint_dribler"
    type="continuous">
    <origin
      xyz="-0.0357459686129146 0.0762500000000002 0.0329999967259823"
      rpy="0 0 0" />
    <parent
      link="base_link" />
    <child
      link="Dribler" />
    <axis
      xyz="-1 0 0" />
  </joint>
  <link
    name="Puncher">
    <inertial>
      <origin
        xyz="-0.0156430860567535 -3.86924650305764E-18 -1.73472347597681E-18"
        rpy="0 0 0" />
      <mass
        value="0.0288061370613567" />
      <inertia
        ixx="0."
        ixy="0"
        ixz="0"
        iyy="0"
        iyz="0"
        izz="0" />
    </inertial>
    <visual>
      <origin
        xyz="0 0 0"
        rpy="0 0 0" />
      <geometry>
        <mesh
          filename="package://omni_robot/meshes/Puncher.STL" />
      </geometry>
      <material
        name="">
        <color
          rgba="0.529411764705882 0.549019607843137 0.549019607843137 1" />
      </material>
    </visual>
    <collision>
      <origin
        xyz="0 0 0"
        rpy="0 0 0" />
      <geometry>
        <mesh
          filename="package://omni_robot/meshes/Puncher.STL" />
      </geometry>
    </collision>
  </link>
  <joint
    name="joint_puncher"
    type="prismatic">
    <origin
      xyz="0 0.0805 0.015"
      rpy="0 0 1.5708" />
    <parent
      link="base_link" />
    <child
      link="Puncher" />
    <axis
      xyz="1 0 0" />
    <limit
      lower="0"
      upper="0.03"
      effort="10"
      velocity="30" />
  </joint>

  <gazebo>
    <plugin name="gazebo_ros_control" filename="libgazebo_ros_control.so">
      <robotNamespace>omni_robot</robotNamespace>
    </plugin>
  </gazebo>


  <transmission name="wfl_trans" type="SimpleTransmission">
    <type>transmission_interface/SimpleTransmission</type>
    <actuator name="wfl_motor">
      <mechanicalReduction>1</mechanicalReduction>
    </actuator>
    <joint name="joint_wfl">
      <hardwareInterface>hardware_interface/VelocityJointInterface</hardwareInterface>
    </joint>
  </transmission>
  
  <transmission name="wfr_trans" type="SimpleTransmission">
    <type>transmission_interface/SimpleTransmission</type>
    <actuator name="wfr_motor">
      <mechanicalReduction>1</mechanicalReduction>
    </actuator>
    <joint name="joint_wfr">
      <hardwareInterface>hardware_interface/VelocityJointInterface</hardwareInterface>
    </joint>
  </transmission>
  
  <transmission name="wbl_trans" type="SimpleTransmission">
    <type>transmission_interface/SimpleTransmission</type>
    <actuator name="wbl_motor">
      <mechanicalReduction>1</mechanicalReduction>
    </actuator>
    <joint name="joint_wbl">
      <hardwareInterface>hardware_interface/VelocityJointInterface</hardwareInterface>
    </joint>
  </transmission>

  <transmission name="wbr_trans" type="SimpleTransmission">
    <type>transmission_interface/SimpleTransmission</type>
    <actuator name="wbr_motor">
      <mechanicalReduction>1</mechanicalReduction>
    </actuator>
    <joint name="joint_wbr">
      <hardwareInterface>hardware_interface/VelocityJointInterface</hardwareInterface>
    </joint>
  </transmission>

    <transmission name="dribler_trans" type="SimpleTransmission">
	<type>transmission_interface/SimpleTransmission</type>
	<actuator name="dribler_motor">
		<mechanicalReduction>1</mechanicalReduction>
	</actuator>
	<joint name="joint_dribler">
		<hardwareInterface>hardware_interface/VelocityJointInterface</hardwareInterface>
	</joint>
  </transmission>

     <transmission name="puncher_trans" type="SimpleTransmission">
	<type>transmission_interface/SimpleTransmission</type>
	<actuator name="puncher_solenoid">
		<mechanicalReduction>1</mechanicalReduction>
	</actuator>
	<joint name="joint_puncher">
		<hardwareInterface>hardware_interface/EffortJointInterface</hardwareInterface>
	</joint>
  </transmission>

</robot>